Workbook

Sheet 1.27.
K1: A | L1: B | M1: C
K2: termék
J3: Termélés és értékesítés db | K3: 1500 | L3: 3000 | M3: 1000
J4: Közvetlen költség Ft/db | K4: 200 | L4: 150 | M4: 300
J5: Üzemi általános költség Ft/db | K5: 50 | L5: 100 | M5: 50
J6: Értékesítés ár Ft/db | K6: 300 | L6: 300 | M6: 500
J7: Normaóra | K7: 4 | L7: 10 | M7: 8
J8: Egységnyi fedezet | K8: =K6-K4-K5 -> 50 | L8: =L6-L4-L5 -> 50 | M8: =M6-M4-M5 -> 150
J9: Relatív fedezet | K9: =K8/K7 -> 12.5 | L9: =L8/L7 -> 5 | M9: =M8/M7 -> 18.75
J10: Termékrangsor: | K10: 2 | L10: 3 | M10: 1
J12: A relatív fedezet alapján a legjövedelmezőbb termék a C termék.
J13: Ha a piac megengedi, akkor ezt érdemes gyártani csak.
J14: Ekkor a fedezeti összeg:
J16: Összes normaóra kapacitás | K16: =SUMPRODUCT(K7:M7,K3:M3) -> 44000
J17: "C" termelési mennyiség: | K17: =K16/M7 -> 5500
J18: összes közvetlen költség: | K18: =M4*K17 -> 1650000
J19: összes üzemi ált. költség: | K19: =K5*K17 -> 275000
J20: árbevétel: | K20: =K17*M6 -> 2750000
J21: összes fedezet | K21: =K20-K19-K18 -> 825000
J23: Előző évi fedezet: | K23: A | L23: B | M23: C
J24: Egységnyi fedezet | K24: 50 | L24: 50 | M24: 150
J25: Termélés és értékesítés db | K25: 1500 | L25: 3000 | M25: 1000
J26: Fedezet | K26: =K24*K25 -> 75000 | L26: =L24*L25 -> 150000 | M26: =M24*M25 -> 150000 | N26: =SUM(K26:M26) -> 375000
J27: Ez alapján, ha csak a C terméket gyártjuk és tudjuk értékesíteni, az 450.000 fedezet növekedéssel jár.
J28: Ha a piac ezt nem teszi lehetővé, a fedezet növelés ennél csak kisebb lehet.
J29: A termékek jövedelmezőségi sorrendje C, A, B, így érdemes a normaóra kapacitást is ilyen sorrendben kihasználni a piaci lehetőségekig.

Sheet 1.fel
A2: Műanyagfeldolgozó iparban működő Kft. a napi fogyasztói igényt a III. üzemében gyártott ötféle műanyag cikkel elégíti ki.
A3: A III. üzemnek a következő időszakban 300.000 EUR általános (fix) költséget kell átvállalnia a központtól, ezenkívül 860.000 EUR rezsiköltség merül fel.
A5: A központi számvitelben a központ fix költségeit a következő arányban osztják fel az öt termék (sorrendben) 2:4:3:5:1 között. Az üzemi rezsi (fix) költségeinek felosztási aránya ugyanerre az öt termékre: 1:2:2:4:1.
A8: A tervidőszak adatai:
A9: Termék | B9: Ár (p) EUR/db | C9: Változó költség (Kp) EUR/db | D9: Max. ért. Menny (Xmax) db
A10: A | B10: 20 | C10: 12 | D10: 25000
A11: B | B11: 18 | C11: 8 | D11: 30000
A12: C | B12: 22 | C12: 10 | D12: 15000
A13: D | B13: 15 | C13: 6 | D13: 50000
A14: E | B14: 10 | C14: 4 | D14: 35000
A15: 1. Az elképzelések kialakítása
A16: 1.1 A központ üzemgazdasági osztálya javasolja, hogy töröljék a termelési programból a C terméket, mégpedig annak érdekében, hogy nagyobb nyereséget érjenek el. Az illetékes termékmenedzser hevesen tiltakozik. Hogyan érvelne Ön?
A19: 1.2. A reklám céljára 25.000 EUR-os egyszeri összeg áll rendelkezésre. Az üzemgazdasági osztály azon a véleményen van, hogy a reklám hatása akkor a legnagyobb, ha egyetlen termékre koncentrálódnak a reklámeszközök. Melyik terméket reklámozná, ha a reklámeszközök alkalmazása mindegyik terméknek az előző táblázatban megadott értékesítési adatait
A22: a. 15%-kal növelné?
A23: b. +10000 db-bal növelné?
A24: 1.3. A II. műhely egyik csigásprésének meghibásodása szűk keresztmetszetet idéz elő, ezért a maximális értékesítési mennyiséget nem tudják legyártani. A szűk keresztmetszeten az egyes termékek termelési ideje a következőképpen alakul:
A26: Termék | B26: Munka (ó/db)
A27: A | B27: 2
A28: B | B28: 2
A29: C | B29: 4
A30: D | B30: 4.5
A31: E | B31: 1
A32: Az egyes termékekből milyen mennyiséget gyártana, ha a nyereséget szeretné maximalizálni a vizsgált időszakban, és ha 259.000 óra áll rendelkezésre a szűk keresztmetszeten.

Sheet 1. fel megoldás
A2: Fedezet és relatív fedezet meghatározása (NY = Árbev-(Kp+Ká) = F - Ká)
A4: Termék | B4: Ár (EUR/db) | C4: Kp (EUR/db) | D4: Max ért. menny. (db) | E4: Árbevétel | F4: Σ Kp | G4: Üzemi Ká | H4: Központi fix ktsg Ká | I4: Össz Ká | J4: Nyereség | K4: Nyereség hányad (%) | L4: Fö (Árbev-Kp) | M4: Fedezeti hányad (%) | P4: Fe
A5: A | B5: ='1.fel'!B10 -> 20 | C5: ='1.fel'!C10 -> 12 | D5: ='1.fel'!D10 -> 25000 | E5: =B5*D5 -> 500000 | F5: =C5*D5 -> 300000 | G5: =B13*A$12/B$18 -> 86000 | H5: =D13*C$12/D$18 -> 40000 | I5: =H5+G5 -> 126000 | J5: =E5-F5-(G5+H5) -> 74000 | K5: =J5/E5 -> 0.148 | L5: =E5-F5 -> 200000 | M5: =L5/E5 -> 0.4 | P5: =B5-C5 -> 8
A6: B | B6: ='1.fel'!B11 -> 18 | C6: ='1.fel'!C11 -> 8 | D6: ='1.fel'!D11 -> 30000 | E6: =B6*D6 -> 540000 | F6: =C6*D6 -> 240000 | G6: =B14*A$12/B$18 -> 172000 | H6: =D14*C$12/D$18 -> 80000 | I6: =H6+G6 -> 252000 | J6: =E6-F6-(G6+H6) -> 48000 | K6: =J6/E6 -> 0.088888889 | L6: =E6-F6 -> 300000 | M6: =L6/E6 -> 0.55555556 | P6: =B6-C6 -> 10
A7: C | B7: ='1.fel'!B12 -> 22 | C7: ='1.fel'!C12 -> 10 | D7: ='1.fel'!D12 -> 15000 | E7: =B7*D7 -> 330000 | F7: =C7*D7 -> 150000 | G7: =B15*A$12/B$18 -> 172000 | H7: =D15*C$12/D$18 -> 60000 | I7: =H7+G7 -> 232000 | J7: =E7-F7-(G7+H7) -> -52000 | K7: - | L7: =E7-F7 -> 180000 | M7: =L7/E7 -> 0.54545455 | P7: =B7-C7 -> 12
A8: D | B8: ='1.fel'!B13 -> 15 | C8: ='1.fel'!C13 -> 6 | D8: ='1.fel'!D13 -> 50000 | E8: =B8*D8 -> 750000 | F8: =C8*D8 -> 300000 | G8: =B16*A$12/B$18 -> 344000 | H8: =D16*C$12/D$18 -> 100000 | I8: =H8+G8 -> 444000 | J8: =E8-F8-(G8+H8) -> 6000 | K8: =J8/E8 -> 0.008 | L8: =E8-F8 -> 450000 | M8: =L8/E8 -> 0.6 | P8: =B8-C8 -> 9
A9: E | B9: ='1.fel'!B14 -> 10 | C9: ='1.fel'!C14 -> 4 | D9: ='1.fel'!D14 -> 35000 | E9: =B9*D9 -> 350000 | F9: =C9*D9 -> 140000 | G9: =B17*A$12/B$18 -> 86000 | H9: =D17*C$12/D$18 -> 20000 | I9: =H9+G9 -> 106000 | J9: =E9-F9-(G9+H9) -> 104000 | K9: =J9/E9 -> 0.29714286 | L9: =E9-F9 -> 210000 | M9: =L9/E9 -> 0.6 | P9: =B9-C9 -> 6
I10: =SUM(I5:I9) -> 1160000 | J10: =SUM(J5:J9) -> 180000 | L10: =SUM(L5:L9) -> 1340000
A11: Σ Üzemi Ká: | C11: Központi fix ktsg Ká | J11: Σ Nyereség:
A12: 860000 | C12: 300000 | E12: üzemi Kf | F12: Központi Kf | J12: =SUM(J5:J9) -> 180000
A13: A | B13: 1 | C13: A | D13: 2 | E13: =$G$20*B13 -> 86000 | F13: =$G$21*D13 -> 40000
A14: B | B14: 2 | C14: B | D14: 4 | E14: =$G$20*B14 -> 172000 | F14: =$G$21*D14 -> 80000
A15: C | B15: 2 | C15: C | D15: 3 | E15: =$G$20*B15 -> 172000 | F15: =$G$21*D15 -> 60000
A16: D | B16: 4 | C16: D | D16: 5 | E16: =$G$20*B16 -> 344000 | F16: =$G$21*D16 -> 100000
A17: E | B17: 1 | C17: E | D17: 1 | E17: =$G$20*B17 -> 86000 | F17: =$G$21*D17 -> 20000
B18: =SUM(B13:B17) -> 10 | D18: =SUM(D13:D17) -> 15 | E18: =SUM(E13:E17) -> 860000 | F18: =SUM(F13:F17) -> 300000 | G18: össz
E20: üzemi Kf/arány | F20: "860000/10=" | G20: 86000
E21: KpiKf/arány=300000/15= | G21: 20000
A24: Nem vesszük ki a 3. terméket, mert azt kivéve több veszteség lenne.
A27: 1.2.
A28: a. A legnagyobb fedezeti összeggel bíró terméket kell reklámozni. 4. terméket reklámozom. b. A legnagyobb egységnyi fedezettel (fajlagos fedezettel) bíró terméket kell reklámozni, 3.terméket reklámozom
A31: 1.3.
A32: Szűk keresztmetszet esetén relatív fedezet alapján döntünk.
A33: Relatív fedezet = Fedezet / Idő
A35: Termék | B35: Max ért. menny. (db) | C35: Munka (ó/db) | D35: Fe Egységnyi (fajlagos) fedezet (EUR/db) | E35: Relatív fedezet | F35: Termék rangsor
A36: A | B36: 25000 | C36: 2 | D36: 8 | E36: =D36/C36 -> 4 | F36: 3
A37: B | B37: 30000 | C37: 2 | D37: 10 | E37: =D37/C37 -> 5 | F37: 2
A38: C | B38: 15000 | C38: 4 | D38: 12 | E38: =D38/C38 -> 3 | F38: 4
A39: D | B39: 50000 | C39: 4.5 | D39: 9 | E39: =D39/C39 -> 2 | F39: 5
A40: E | B40: 35000 | C40: 1 | D40: 6 | E40: =D40/C40 -> 6 | F40: 1
A43: Σ idő: | B43: Σ idő: | C43: 259000
A44: Termékek rangsor | B44: Termékek | C44: Max. ért. (db) | D44: óra/db | F44: Eddig felhasznált gépidő
A45: 1 | B45: E | C45: =D9 -> 35000 | D45: 1 | E45: =C45*D45 -> 35000 | F45: 35000
A46: 2 | B46: B | C46: =D6 -> 30000 | D46: 2 | E46: =C46*D46 -> 60000 | F46: =F45+E46 -> 95000
A47: 3 | B47: A | C47: 25000 | D47: 2 | E47: =C47*D47 -> 50000 | F47: =F46+E47 -> 145000
A48: 4 | B48: C | C48: 15000 | D48: 4 | E48: =C48*D48 -> 60000 | F48: =F47+E48 -> 205000
A49: 5 | B49: D | C49: 50000 | D49: 4.5 | E49: =C49*D49 -> 225000 | F49: =F48+E49 -> 430000 | G49: nincs ennyi gépidőnk
A50: Marad: | B50: D | C50: 12000 | D50: 4.5 | E50: 54000 | F50: =F48+E50 -> 259000 | G50: maradék gépidő= 259000-205000
A51: =C43-F48 -> 54000 | B51: óra a D termék
A52: =A51/[1]Feladat!B31 -> 12000 | B52: db D termék
...
